<?xml version="1.0" encoding="utf-8"?>
<!-- This URDF was automatically created by SolidWorks to URDF Exporter! Originally created by Stephen Brawner (brawner@gmail.com) 
     Commit Version: 1.6.0-1-g15f4949  Build Version: 1.6.7594.29634
     For more information, please see http://wiki.ros.org/sw_urdf_exporter -->
<robot
  name="newbot2">
  <link name="world">
  </link>
  <joint
    name="world_J"
    type="fixed">
    <parent link="world"/>
    <child link="base_link"/>
  </joint>

  <link
    name="base_link">
    <inertial>
      <origin
        xyz="-0.0024903442012708 2.61342180056364E-19 0.229616"
        rpy="0 0 0" />
      <mass
        value="11.0110587542618" />
      <inertia
        ixx="0.236170687813653"
        ixy="7.64935441596338E-17"
        ixz="2.59145699930236E-19"
        iyy="0.454825212618061"
        iyz="4.68308850116304E-19"
        izz="0.690699904820635" />
    </inertial>
    <visual>
      <origin
        xyz="0 0 0"
        rpy="0 0 0" />
      <geometry>
        <mesh
          filename="package://newbot2/meshes/base_link.STL" />
      </geometry>
      <material
        name="">
        <color
          rgba="0.847058823529412 0.847058823529412 0.847058823529412 1" />
      </material>
    </visual>
    <collision>
      <origin
        xyz="0 0 0"
        rpy="0 0 0" />
      <geometry>
        <mesh
          filename="package://newbot2/meshes/base_link.STL" />
      </geometry>
    </collision>
  </link>
  <link
    name="FL_L">
    <inertial>
      <origin
        xyz="5.55111512312578E-17 -0.0150317886588243 -0.0884514952091744"
        rpy="0 0 0" />
      <mass
        value="1.19229443464426" />
      <inertia
        ixx="0.00341724741154984"
        ixy="-2.44215429815691E-19"
        ixz="-3.12486381065568E-19"
        iyy="0.00273734926033021"
        iyz="-0.000824153890762725"
        izz="0.000818318452755266" />
    </inertial>
    <visual>
      <origin
        xyz="0 0 0"
        rpy="0 0 0" />
      <geometry>
        <mesh
          filename="package://newbot2/meshes/FL_L.STL" />
      </geometry>
      <material
        name="">
        <color
          rgba="0.529411764705882 0.549019607843137 0.549019607843137 1" />
      </material>
    </visual>
    <collision>
      <origin
        xyz="0 0 0"
        rpy="0 0 0" />
      <geometry>
        <mesh
          filename="package://newbot2/meshes/FL_L.STL" />
      </geometry>
    </collision>
  </link>
  <joint
    name="FL_J"
    type="continuous">
    <origin
      xyz="0.254 -0.2032 0.23597"
      rpy="0 0 0" />
    <parent
      link="base_link" />
    <child
      link="FL_L" />
    <axis
      xyz="0 0 1" />
  </joint>
  <link
    name="WFL_L">
    <inertial>
      <origin
        xyz="0 -0.0254000000000001 0"
        rpy="0 0 0" />
      <mass
        value="0.886563918408615" />
      <inertia
        ixx="0.0031294160757788"
        ixy="1.5678257667547E-18"
        ixz="-1.60794734545388E-19"
        iyy="0.00590313893142078"
        iyz="-7.34853173931389E-19"
        izz="0.0031294160757788" />
    </inertial>
    <visual>
      <origin
        xyz="0 0 0"
        rpy="0 0 0" />
      <geometry>
        <mesh
          filename="package://newbot2/meshes/WFL_L.STL" />
      </geometry>
      <material
        name="">
        <color
          rgba="0.298039215686275 0.298039215686275 0.298039215686275 1" />
      </material>
    </visual>
    <collision>
      <origin
        xyz="0 0 0"
        rpy="0 0 0" />
      <geometry>
        <mesh
          filename="package://newbot2/meshes/WFL_L.STL" />
      </geometry>
    </collision>
  </link>
  <joint
    name="WFL_J"
    type="continuous">
    <origin
      xyz="0 -0.02251 -0.13438"
      rpy="0 0 0" />
    <parent
      link="FL_L" />
    <child
      link="WFL_L" />
    <axis
      xyz="0 1 0" />
  </joint>
  <link
    name="FR_L">
    <inertial>
      <origin
        xyz="-8.88178419700125E-16 0.0150317886588243 -0.0884514952091771"
        rpy="0 0 0" />
      <mass
        value="1.19229443464426" />
      <inertia
        ixx="0.00341724741154984"
        ixy="8.38215077697555E-18"
        ixz="-2.67413334511279E-17"
        iyy="0.00273734926033021"
        iyz="0.000824153890762725"
        izz="0.000818318452755266" />
    </inertial>
    <visual>
      <origin
        xyz="0 0 0"
        rpy="0 0 0" />
      <geometry>
        <mesh
          filename="package://newbot2/meshes/FR_L.STL" />
      </geometry>
      <material
        name="">
        <color
          rgba="0.529411764705882 0.549019607843137 0.549019607843137 1" />
      </material>
    </visual>
    <collision>
      <origin
        xyz="0 0 0"
        rpy="0 0 0" />
      <geometry>
        <mesh
          filename="package://newbot2/meshes/FR_L.STL" />
      </geometry>
    </collision>
  </link>
  <joint
    name="FR_J"
    type="continuous">
    <origin
      xyz="0.254 0.2032 0.23597"
      rpy="0 0 0" />
    <parent
      link="base_link" />
    <child
      link="FR_L" />
    <axis
      xyz="0 0 1" />
  </joint>
  <link
    name="WFR_L">
    <inertial>
      <origin
        xyz="-1.55431223447522E-15 0.0254 6.93889390390723E-16"
        rpy="0 0 0" />
      <mass
        value="0.886563918408615" />
      <inertia
        ixx="0.0031294160757788"
        ixy="8.62985748336241E-19"
        ixz="1.46038737146381E-20"
        iyy="0.00590313893142079"
        iyz="3.87599152230217E-17"
        izz="0.0031294160757788" />
    </inertial>
    <visual>
      <origin
        xyz="0 0 0"
        rpy="0 0 0" />
      <geometry>
        <mesh
          filename="package://newbot2/meshes/WFR_L.STL" />
      </geometry>
      <material
        name="">
        <color
          rgba="0.298039215686275 0.298039215686275 0.298039215686275 1" />
      </material>
    </visual>
    <collision>
      <origin
        xyz="0 0 0"
        rpy="0 0 0" />
      <geometry>
        <mesh
          filename="package://newbot2/meshes/WFR_L.STL" />
      </geometry>
    </collision>
  </link>
  <joint
    name="WFR_J"
    type="continuous">
    <origin
      xyz="0 0.02251 -0.13438"
      rpy="0 0 0" />
    <parent
      link="FR_L" />
    <child
      link="WFR_L" />
    <axis
      xyz="0 1 0" />
  </joint>
  <link
    name="RL_L">
    <inertial>
      <origin
        xyz="-5.55111512312578E-17 -0.0150317886588243 -0.0884514952091744"
        rpy="0 0 0" />
      <mass
        value="1.19229443464426" />
      <inertia
        ixx="0.00341724741154984"
        ixy="-2.46828352278768E-19"
        ixz="-3.00038040152971E-19"
        iyy="0.00273734926033021"
        iyz="-0.000824153890762725"
        izz="0.000818318452755266" />
    </inertial>
    <visual>
      <origin
        xyz="0 0 0"
        rpy="0 0 0" />
      <geometry>
        <mesh
          filename="package://newbot2/meshes/RL_L.STL" />
      </geometry>
      <material
        name="">
        <color
          rgba="0.529411764705882 0.549019607843137 0.549019607843137 1" />
      </material>
    </visual>
    <collision>
      <origin
        xyz="0 0 0"
        rpy="0 0 0" />
      <geometry>
        <mesh
          filename="package://newbot2/meshes/RL_L.STL" />
      </geometry>
    </collision>
  </link>
  <joint
    name="RL_J"
    type="fixed">
    <origin
      xyz="-0.254 -0.2032 0.23597"
      rpy="0 0 0" />
    <parent
      link="base_link" />
    <child
      link="RL_L" />
    <axis
      xyz="0 0 1" />
  </joint>
  <link
    name="WRL_L">
    <inertial>
      <origin
        xyz="0 -0.0254000000000001 2.77555756156289E-17"
        rpy="0 0 0" />
      <mass
        value="0.886563918408615" />
      <inertia
        ixx="0.0031294160757788"
        ixy="9.65085875607427E-19"
        ixz="-3.6841590507346E-19"
        iyy="0.00590313893142079"
        iyz="-7.45163796327642E-19"
        izz="0.0031294160757788" />
    </inertial>
    <visual>
      <origin
        xyz="0 0 0"
        rpy="0 0 0" />
      <geometry>
        <mesh
          filename="package://newbot2/meshes/WRL_L.STL" />
      </geometry>
      <material
        name="">
        <color
          rgba="0.298039215686275 0.298039215686275 0.298039215686275 1" />
      </material>
    </visual>
    <collision>
      <origin
        xyz="0 0 0"
        rpy="0 0 0" />
      <geometry>
        <mesh
          filename="package://newbot2/meshes/WRL_L.STL" />
      </geometry>
    </collision>
  </link>
  <joint
    name="WRL_J"
    type="continuous">
    <origin
      xyz="0 -0.02251 -0.13438"
      rpy="0 0 0" />
    <parent
      link="RL_L" />
    <child
      link="WRL_L" />
    <axis
      xyz="0 1 0" />
  </joint>
  <link
    name="RR_L">
    <inertial>
      <origin
        xyz="-9.43689570931383E-16 0.0150317886588243 -0.0884514952091717"
        rpy="0 0 0" />
      <mass
        value="1.19229443464426" />
      <inertia
        ixx="0.00341724741154984"
        ixy="8.38215077697555E-18"
        ixz="-2.67413334511279E-17"
        iyy="0.00273734926033021"
        iyz="0.000824153890762725"
        izz="0.000818318452755266" />
    </inertial>
    <visual>
      <origin
        xyz="0 0 0"
        rpy="0 0 0" />
      <geometry>
        <mesh
          filename="package://newbot2/meshes/RR_L.STL" />
      </geometry>
      <material
        name="">
        <color
          rgba="0.529411764705882 0.549019607843137 0.549019607843137 1" />
      </material>
    </visual>
    <collision>
      <origin
        xyz="0 0 0"
        rpy="0 0 0" />
      <geometry>
        <mesh
          filename="package://newbot2/meshes/RR_L.STL" />
      </geometry>
    </collision>
  </link>
  <joint
    name="RR_J"
    type="fixed">
    <origin
      xyz="-0.254 0.2032 0.23597"
      rpy="0 0 0" />
    <parent
      link="base_link" />
    <child
      link="RR_L" />
    <axis
      xyz="0 0 1" />
  </joint>
  <link
    name="WRR_L">
    <inertial>
      <origin
        xyz="-1.55431223447522E-15 0.0253999999999999 6.24500451351651E-15"
        rpy="0 0 0" />
      <mass
        value="0.886563918408614" />
      <inertia
        ixx="0.0031294160757788"
        ixy="8.74659166709833E-19"
        ixz="-1.99696909506642E-20"
        iyy="0.00590313893142078"
        iyz="3.87713552787215E-17"
        izz="0.0031294160757788" />
    </inertial>
    <visual>
      <origin
        xyz="0 0 0"
        rpy="0 0 0" />
      <geometry>
        <mesh
          filename="package://newbot2/meshes/WRR_L.STL" />
      </geometry>
      <material
        name="">
        <color
          rgba="0.298039215686275 0.298039215686275 0.298039215686275 1" />
      </material>
    </visual>
    <collision>
      <origin
        xyz="0 0 0"
        rpy="0 0 0" />
      <geometry>
        <mesh
          filename="package://newbot2/meshes/WRR_L.STL" />
      </geometry>
    </collision>
  </link>
  <joint
    name="WRR_J"
    type="continuous">
    <origin
      xyz="0 0.02251 -0.13438"
      rpy="0 0 0" />
    <parent
      link="RR_L" />
    <child
      link="WRR_L" />
    <axis
      xyz="0 1 0" />
  </joint>
</robot>
